Workbook
Name NativeTimeline_Date: #N/A
Name Slicer_CustomerName: #N/A
Name Slicer_Date: #N/A
Name Slicer_Product: #N/A
Name Slicer_Region: #N/A
Name Slicer_SalesRep: #N/A
Name Slicer_TotalSales: #N/A

Sheet MessySalesTable
A1: OrderID | B1: Date | C1: CustomerName | D1: Product | E1: Qty | F1: UnitPrice | G1: Region | H1: SalesRep | I1: Status | J1: LeadSource | K1: Notes
A2: 1028 | B2: 23/03/2025 | C2: Jane Doe | D2: Widget B | E2: 2 | F2: 45.5 | G2: London | H2: A. Smith | I2: Completed | J2: Email
A3: 1016 | B3: 45727 | C3: Lisa O'neil | D3: Widget D | E3: 1 | F3: 125 | G3: Leeds | H3: D. Green | I3: Completed | J3: Web
A4: 1024 | B4: 19/03/2025 | C4: Jane-Doe | D4: Widget B | E4: 1 | F4: 45.5 | G4: LONDON | H4: A. Smith | I4: Completed | J4: Email
A5: 1018 | B5: 13/03/2025 | C5: Mary Johnson | D5: Widget B | E5: 2 | F5: 45.5 | G5: London | H5: A. Smith | I5: Completed | J5: Web
A6: 1009 | B6: 45841 | C6: Mary Johnson | D6: Widget C | E6: 2 | F6: 60 | G6: London | H6: A. Smith | I6: Completed | J6: Web
A7: 1010 | B7: 45724 | C7: steve o'brien | D7: Widget B | E7: 3 | F7: Â£45.50 | G7: Manchester | H7: B. O'Connor | I7: Completed | J7: Email
A8: 1029 | B8: 24/03/2025 | C8: Mary Johnson | D8: Widget C | E8: 3 | F8: 60 | G8: London | H8: A. Smith | I8: Completed | J8: Web
A9: 1025 | B9: 20/03/2025 | C9: Mary Johnson | D9: Widget C | F9: 60 | G9: London | H9: A. Smith | I9: Pending | J9: Web | K9: missing qty
A10: 1013 | B10: 45725 | C10: ACME corp | D10: Widget D | E10: 2 | F10: 125 | G10: Birmingham | H10: C. Patel | I10: Pending | J10: Email | K10: international
A11: 1001 | B11: 45660 | C11: Jane Doe | D11: Widget A | E11: 2 | F11: 25 | G11: London | H11: A. Smith | I11: Completed | J11: Referral | K11: Paid via bank
A12: 1005 | B12: 45720 | C12: jane doe | D12: Widget B | E12: 2 | F12: 45.5 | G12: London | H12: A. Smith | I12: Completed | J12: Email
A13: 1017 | B13: 45728 | C13: ACME CORP | D13: Widget C | E13: 3 | F13: 60 | G13: Birmingham | H13: C. Patel | I13: Completed | J13: Email
A14: 1006 | B14: 45720 | C14: John Smith | D14: Widget A | F14: 25 | G14: Manchester | H14: B. O'Connor | I14: Pending | J14: Phone | K14: missing qty
A15: 1014 | B15: 45933 | C15: Bob | D15: Widget B | E15: 2 | F15: 45,50 | G15: Manchester | H15: B. O'Connor | I15: Completed | J15: Phone
A16: 1012 | B16: 2025.03.09 | C16: Anne Marie | D16: Widget A | E16: 1 | F16: 25 | G16: London | H16: A. Smith | I16: Completed | J16: Referral
A17: 1023 | B17: 45734 | C17: ACME CORP | D17: Widget A | E17: 8 | F17: 24.5 | G17: B'ham | H17: C. Patel | I17: Completed | J17: Referral
A18: 1002 | B18: 45717 | C18: john smith | D18: Widget B | E18: 1 | F18: 45.5 | G18: Manchester | H18: B. O'Connor | I18: Pending | J18: Email Campaign
A19: 1003 | B19: 45718 | C19: Mary Johnson | D19: Widget A | E19: 5 | F19: 25 | G19: london | H19: A. Smith | I19: Completed | J19: Web | K19: urgent
A20: 1026 | B20: 21/03/2025 | C20: ACME CORP | D20: Widget A | E20: 5 | F20: 24.5 | G20: Birmingham | H20: C. Patel | I20: Completed | J20: Referral
A21: 1004 | B21: 45719 | C21: ACME CORP | D21: Widget C | E21: 3 | F21: Â£60.00 | G21: Birmingham | H21: C. Patel | I21: Completed | J21: Referral
A22: 1022 | B22: 17/03/2025 | C22: Mary Johnson | D22: Widget C | E22: two | F22: 60 | G22: London | H22: A. Smith | I22: Pending | J22: Phone | K22: qty as text
A23: 1027 | B23: 22/03/2025 | C23: Paul Akporarhe | D23: Widget G | E23: 1 | F23: 300 | G23: Abuja | H23: P. Akporarhe | I23: Completed | J23: Direct | K23: internal test
A24: 1019 | B24: 14/03/2025 | C24: JANE DOE | D24: Widget A | E24: 1 | F24: 25 | G24: London | H24: A. Smith | I24: Completed | J24: Referral
A25: 1030 | B25: 25/03/2025 | C25: ACME Corp. | D25: Widget A | E25: 2 | F25: 24,50 | G25: Birmingham | H25: C. Patel | I25: Completed | J25: Referral
A26: 1021 | B26: 16/03/2025 | C26: O'Connor, Brian | D26: Widget B | E26: 2 | F26: 45.5 | G26: Manchester | H26: B. O'Connor | I26: Completed | J26: Email
A27: 1008 | B27: 45811 | C27: ACME CORP | D27: Widget A | E27: 10 | F27: 24.5 | G27: Birmingham | H27: C. Patel | I27: Completed | J27: Referral
A28: 1011 | B28: 45724 | C28: Mary-Jane | D28: Widget E | E28: 2 | F28: 200 | G28: Leeds | H28: D. Green | I28: Pending | J28: Web | K28: special price
A29: 1015 | B29: 45727 | C29: jane doe | D29: Widget A | E29: 4 | F29: 25 | G29: london | H29: A. Smith | I29: Completed | J29: Referral
A30: 1020 | B30: 15-03-2025 | C30: Unknown | D30: Widget F | E30: 1 | F30: 0 | G30: Unknown | I30: Pending | J30: Referral | K30: needs follow-up
A31: 1007 | B31: 45780 | C31: Lisa O'Neil | D31: Widget D | E31: 1 | F31: 125 | G31: Leeds | H31: D. Green | I31: Completed | J31: Web

Sheet CleanSalesTable
A1: OrderID | B1: Date | C1: CustomerName | D1: Product | E1: UnitPrice | F1: Qty | G1: Region | H1: SalesRep | I1: TotalSales | J1: Status | K1: LeadSource | L1: Notes | N1: Product | O1: Price
A2: 1006 | B2: 45720 | C2: John Smith | D2: Widget A | E2: 25 | F2: 60 | G2: Manchester | H2: B. O'Connor | I2: =SalesRawClean[[#This Row],[Qty]] * SalesRawClean[[#This Row],[UnitPrice]] -> 1500 | J2: Pending | K2: Phone | L2: missing qty | N2: Widget A | O2: =VLOOKUP(N2,SalesRawClean[[Product]:[UnitPrice]],2,FALSE) -> 25
A3: 1011 | B3: 45724 | C3: Mary Jane | D3: Widget E | E3: 200 | F3: 2 | G3: Leeds | H3: D. Green | I3: =SalesRawClean[[#This Row],[Qty]] * SalesRawClean[[#This Row],[UnitPrice]] -> 400 | J3: Pending | K3: Web | L3: special price | N3: Widget B | O3: =VLOOKUP(N3,SalesRawClean[[Product]:[UnitPrice]],2,FALSE) -> 45.5
A4: 1025 | B4: 45736 | C4: Mary Johnson | D4: Widget C | E4: 60 | F4: 5 | G4: London | H4: A. Smith | I4: =SalesRawClean[[#This Row],[Qty]] * SalesRawClean[[#This Row],[UnitPrice]] -> 300 | J4: Pending | K4: Web | L4: missing qty | N4: Widget C | O4: =VLOOKUP(N4,SalesRawClean[[Product]:[UnitPrice]],2,FALSE) -> 60
A5: 1027 | B5: 45738 | C5: Paul Akporarhe | D5: Widget G | E5: 300 | F5: 1 | G5: Abuja | H5: P. Akporarhe | I5: =SalesRawClean[[#This Row],[Qty]] * SalesRawClean[[#This Row],[UnitPrice]] -> 300 | J5: Completed | K5: Direct | L5: internal test | N5: Widget D | O5: =VLOOKUP(N5,SalesRawClean[[Product]:[UnitPrice]],2,FALSE) -> 125
A6: 1002 | B6: 45660 | C6: John Smith | D6: Widget B | E6: 45.5 | F6: 6 | G6: Manchester | H6: B. O'Connor | I6: =SalesRawClean[[#This Row],[Qty]] * SalesRawClean[[#This Row],[UnitPrice]] -> 273 | J6: Pending | K6: Email | N6: Widget E | O6: =VLOOKUP(N6,SalesRawClean[[Product]:[UnitPrice]],2,FALSE) -> 200
A7: 1013 | B7: 45725 | C7: Acme Corp | D7: Widget D | E7: 125 | F7: 2 | G7: Birmingham | H7: C. Patel | I7: =SalesRawClean[[#This Row],[Qty]] * SalesRawClean[[#This Row],[UnitPrice]] -> 250 | J7: Pending | K7: Email | L7: international | N7: Widget F | O7: =VLOOKUP(N7,SalesRawClean[[Product]:[UnitPrice]],2,FALSE) -> 20
A8: 1008 | B8: 45722 | C8: Acme Corp | D8: Widget A | E8: 24.5 | F8: 10 | G8: Birmingham | H8: C. Patel | I8: =SalesRawClean[[#This Row],[Qty]] * SalesRawClean[[#This Row],[UnitPrice]] -> 245 | J8: Completed | K8: Referral | N8: Widget G | O8: =VLOOKUP(N8,SalesRawClean[[Product]:[UnitPrice]],2,FALSE) -> 300
A9: 1020 | B9: 45731 | C9: Jeffery Donovan | D9: Widget F | E9: 20 | F9: 10 | G9: california | H9: Alice Undav | I9: =SalesRawClean[[#This Row],[Qty]] * SalesRawClean[[#This Row],[UnitPrice]] -> 200 | J9: Pending | K9: Referral | L9: needs follow-up
A10: 1023 | B10: 45734 | C10: Acme Corp | D10: Widget A | E10: 24.5 | F10: 8 | G10: Birmingham | H10: C. Patel | I10: =SalesRawClean[[#This Row],[Qty]] * SalesRawClean[[#This Row],[UnitPrice]] -> 196 | J10: Completed | K10: Referral
A11: 1004 | B11: 45719 | C11: Acme Corp | D11: Widget C | E11: 60 | F11: 3 | G11: Birmingham | H11: C. Patel | I11: =SalesRawClean[[#This Row],[Qty]] * SalesRawClean[[#This Row],[UnitPrice]] -> 180 | J11: Completed | K11: Referral
A12: 1017 | B12: 45728 | C12: Acme Corp | D12: Widget C | E12: 60 | F12: 3 | G12: Birmingham | H12: C. Patel | I12: =SalesRawClean[[#This Row],[Qty]] * SalesRawClean[[#This Row],[UnitPrice]] -> 180 | J12: Completed | K12: Email | N12: TotalOrders | O12: =COUNTA(SalesRawClean[OrderID]) -> 30
A13: 1029 | B13: 45740 | C13: Mary Johnson | D13: Widget C | E13: 60 | F13: 3 | G13: London | H13: A. Smith | I13: =SalesRawClean[[#This Row],[Qty]] * SalesRawClean[[#This Row],[UnitPrice]] -> 180 | J13: Completed | K13: Web | N13: TotalRevenue | O13: =SUM(SalesRawClean[TotalSales]) -> 5827.5
A14: 1010 | B14: 45872 | C14: Steve O'Brien | D14: Widget B | E14: 45.5 | F14: 3 | G14: Manchester | H14: B. O'Connor | I14: =SalesRawClean[[#This Row],[Qty]] * SalesRawClean[[#This Row],[UnitPrice]] -> 136.5 | J14: Completed | K14: Email | N14: AvgOrderValue | O14: =IF(COUNTA(SalesRawClean[OrderID])=0,0,SUM(SalesRawClean[TotalSales])/COUNTA(SalesRawClean[OrderID])) -> 194.25
A15: 1003 | B15: 45691 | C15: Mary Johnson | D15: Widget A | E15: 25 | F15: 5 | G15: London | H15: A. Smith | I15: =SalesRawClean[[#This Row],[Qty]] * SalesRawClean[[#This Row],[UnitPrice]] -> 125 | J15: Completed | K15: Web | L15: urgent | N15: Widget A | O15: =SUMIFS(SalesRawClean[TotalSales], SalesRawClean[Product], N15) -> 2437.5 | P15: =MAX(O15:O21) -> 2437.5
A16: 1007 | B16: 45721 | C16: Lisa O'Neil | D16: Widget D | E16: 125 | F16: 1 | G16: Leeds | H16: D. Green | I16: =SalesRawClean[[#This Row],[Qty]] * SalesRawClean[[#This Row],[UnitPrice]] -> 125 | J16: Completed | K16: Web | N16: Widget C | O16: =SUMIFS(SalesRawClean[TotalSales], SalesRawClean[Product], N16) -> 1080 | P16: =INDEX(N15:N21, MATCH(P15, O15:O21, 0)) -> Widget A
A17: 1016 | B17: 45964 | C17: Lisa O'Neil | D17: Widget D | E17: 125 | F17: 1 | G17: Leeds | H17: D. Green | I17: =SalesRawClean[[#This Row],[Qty]] * SalesRawClean[[#This Row],[UnitPrice]] -> 125 | J17: Completed | K17: Web | N17: Widget B | O17: =SUMIFS(SalesRawClean[TotalSales], SalesRawClean[Product], N17) -> 910
A18: 1026 | B18: 45737 | C18: Acme Corp | D18: Widget A | E18: 24.5 | F18: 5 | G18: Birmingham | H18: C. Patel | I18: =SalesRawClean[[#This Row],[Qty]] * SalesRawClean[[#This Row],[UnitPrice]] -> 122.5 | J18: Completed | K18: Referral | N18: Widget D | O18: =SUMIFS(SalesRawClean[TotalSales], SalesRawClean[Product], N18) -> 500
A19: 1009 | B19: 45723 | C19: Mary Johnson | D19: Widget C | E19: 60 | F19: 2 | G19: London | H19: A. Smith | I19: =SalesRawClean[[#This Row],[Qty]] * SalesRawClean[[#This Row],[UnitPrice]] -> 120 | J19: Completed | K19: Web | N19: Widget E | O19: =SUMIFS(SalesRawClean[TotalSales], SalesRawClean[Product], N19) -> 400
A20: 1022 | B20: 45733 | C20: Mary Johnson | D20: Widget C | E20: 60 | F20: 2 | G20: London | H20: A. Smith | I20: =SalesRawClean[[#This Row],[Qty]] * SalesRawClean[[#This Row],[UnitPrice]] -> 120 | J20: Pending | K20: Phone | L20: qty as text | N20: Widget G | O20: =SUMIFS(SalesRawClean[TotalSales], SalesRawClean[Product], N20) -> 300
A21: 1015 | B21: 45964 | C21: Jane Doe | D21: Widget A | E21: 25 | F21: 4 | G21: London | H21: A. Smith | I21: =SalesRawClean[[#This Row],[Qty]] * SalesRawClean[[#This Row],[UnitPrice]] -> 100 | J21: Completed | K21: Referral | N21: Widget F | O21: =SUMIFS(SalesRawClean[TotalSales], SalesRawClean[Product], N21) -> 200
A22: 1014 | B22: 45726 | C22: Bob | D22: Widget B | E22: 45.5 | F22: 2 | G22: Manchester | H22: B. O'Connor | I22: =SalesRawClean[[#This Row],[Qty]] * SalesRawClean[[#This Row],[UnitPrice]] -> 91 | J22: Completed | K22: Phone
A23: 1018 | B23: 45729 | C23: Mary Johnson | D23: Widget B | E23: 45.5 | F23: 2 | G23: London | H23: A. Smith | I23: =SalesRawClean[[#This Row],[Qty]] * SalesRawClean[[#This Row],[UnitPrice]] -> 91 | J23: Completed | K23: Web
A24: 1021 | B24: 45732 | C24: O'Connor Brian | D24: Widget B | E24: 45.5 | F24: 2 | G24: Manchester | H24: B. O'Connor | I24: =SalesRawClean[[#This Row],[Qty]] * SalesRawClean[[#This Row],[UnitPrice]] -> 91 | J24: Completed | K24: Email
A25: 1028 | B25: 45739 | C25: Jane Doe | D25: Widget B | E25: 45.5 | F25: 2 | G25: London | H25: A. Smith | I25: =SalesRawClean[[#This Row],[Qty]] * SalesRawClean[[#This Row],[UnitPrice]] -> 91 | J25: Completed | K25: Email
A26: 1005 | B26: 45750 | C26: Jane Doe | D26: Widget B | E26: 45.5 | F26: 2 | G26: London | H26: A. Smith | I26: =SalesRawClean[[#This Row],[Qty]] * SalesRawClean[[#This Row],[UnitPrice]] -> 91 | J26: Completed | K26: Email
A27: 1001 | B27: 45717 | C27: Jane Doe | D27: Widget A | E27: 25 | F27: 2 | G27: London | H27: A. Smith | I27: =SalesRawClean[[#This Row],[Qty]] * SalesRawClean[[#This Row],[UnitPrice]] -> 50 | J27: Completed | K27: Referral | L27: Paid via bank
A28: 1030 | B28: 45741 | C28: Acme Corp | D28: Widget A | E28: 24.5 | F28: 2 | G28: Birmingham | H28: C. Patel | I28: =SalesRawClean[[#This Row],[Qty]] * SalesRawClean[[#This Row],[UnitPrice]] -> 49 | J28: Completed | K28: Referral
A29: 1024 | B29: 45735 | C29: Jane Doe | D29: Widget B | E29: 45.5 | F29: 1 | G29: London | H29: A. Smith | I29: =SalesRawClean[[#This Row],[Qty]] * SalesRawClean[[#This Row],[UnitPrice]] -> 45.5 | J29: Completed | K29: Email
A30: 1012 | B30: 45725 | C30: Anne Marie | D30: Widget A | E30: 25 | F30: 1 | G30: London | H30: A. Smith | I30: =SalesRawClean[[#This Row],[Qty]] * SalesRawClean[[#This Row],[UnitPrice]] -> 25 | J30: Completed | K30: Referral
A31: 1019 | B31: 45730 | C31: Jane Doe | D31: Widget A | E31: 25 | F31: 1 | G31: London | H31: A. Smith | I31: =SalesRawClean[[#This Row],[Qty]] * SalesRawClean[[#This Row],[UnitPrice]] -> 25 | J31: Completed | K31: Referral

Sheet SalesPivotTable
M2: Product | N2: Sum of TotalSales | O2: Count of TotalSales | P2: Percentage of TotalSales
A3: Region | B3: Sum of TotalSales in Region | C3: Count of TotalSales in Region | D3: Percentage of TotalSales in Region | M3: Widget C | N3: 720 | O3: 4 | P3: 0.52805281
A4: London | B4: 1363.5 | C4: 13 | D4: 1 | M4: Widget A | N4: 325 | O4: 5 | P4: 0.23835717
A5: Grand Total | B5: 1363.5 | C5: 13 | D5: 1 | M5: Widget B | N5: 318.5 | O5: 4 | P5: 0.23359003
M6: Grand Total | N6: 1363.5 | O6: 13 | P6: 1
A25: LeadSource | B25: Sum of TotalSales | C25: Percentage of TotalSales
A26: Web | B26: 816 | C26: 0.59845985
A27: Email | B27: 227.5 | C27: 0.16685002
A28: Referral | B28: 200 | C28: 0.14668133
A29: Phone | B29: 120 | C29: 0.088008801
A30: Grand Total | B30: 1363.5 | C30: 1
AC37: SalesRep | AD37: Sum of TotalSales | AE37: Count of TotalSales | AF37: Percentage of TotalSales
AC38: A. Smith | AD38: 1363.5 | AE38: 13 | AF38: 1
AC39: Grand Total | AD39: 1363.5 | AE39: 13 | AF39: 1
B44: Date | C44: Sum of TotalSales | D44: Percentage of TotalSales
B45: Feb | C45: 125 | D45: 0.091675834
B46: 3-Feb | C46: 125 | D46: 0.091675834
B47: 45691 | C47: 125 | D47: 0.091675834
B48: Mar | C48: 1047.5 | D48: 0.76824349
B49: 1-Mar | C49: 50 | D49: 0.036670334 | L49: Date | M49: Count of Qty | N49: Sum of Qty | O49: Percentageof Qty
B50: 45717 | C50: 50 | D50: 0.036670334 | F50: CustomerName | G50: Sum of TotalSales | H50: Count of TotalSales | I50: Percentage of TotalSales | L50: Feb | M50: 1 | N50: 5 | O50: 0.15625
B51: 7-Mar | C51: 120 | D51: 0.088008801 | F51: Mary Johnson | G51: 936 | H51: 6 | I51: 0.68646865 | L51: 3-Feb | M51: 1 | N51: 5 | O51: 0.15625
B52: 45723 | C52: 120 | D52: 0.088008801 | F52: Jane Doe | G52: 402.5 | H52: 6 | I52: 0.29519619 | L52: Mar | M52: 10 | N52: 21 | O52: 0.65625
B53: 9-Mar | C53: 25 | D53: 0.018335167 | F53: Anne Marie | G53: 25 | H53: 1 | I53: 0.018335167 | L53: 1-Mar | M53: 1 | N53: 2 | O53: 0.0625
B54: 45725 | C54: 25 | D54: 0.018335167 | F54: Grand Total | G54: 1363.5 | H54: 13 | I54: 1 | L54: 7-Mar | M54: 1 | N54: 2 | O54: 0.0625
B55: 13-Mar | C55: 91 | D55: 0.066740007 | L55: 9-Mar | M55: 1 | N55: 1 | O55: 0.03125
B56: 45729 | C56: 91 | D56: 0.066740007 | L56: 13-Mar | M56: 1 | N56: 2 | O56: 0.0625
B57: 14-Mar | C57: 25 | D57: 0.018335167 | L57: 14-Mar | M57: 1 | N57: 1 | O57: 0.03125
B58: 45730 | C58: 25 | D58: 0.018335167 | L58: 17-Mar | M58: 1 | N58: 2 | O58: 0.0625
B59: 17-Mar | C59: 120 | D59: 0.088008801 | L59: 19-Mar | M59: 1 | N59: 1 | O59: 0.03125
B60: 45733 | C60: 120 | D60: 0.088008801 | L60: 20-Mar | M60: 1 | N60: 5 | O60: 0.15625
B61: 19-Mar | C61: 45.5 | D61: 0.033370004 | L61: 23-Mar | M61: 1 | N61: 2 | O61: 0.0625
B62: 45735 | C62: 45.5 | D62: 0.033370004 | L62: 24-Mar | M62: 1 | N62: 3 | O62: 0.09375
B63: 20-Mar | C63: 300 | D63: 0.220022 | L63: Apr | M63: 1 | N63: 2 | O63: 0.0625
B64: 45736 | C64: 300 | D64: 0.220022 | L64: 3-Apr | M64: 1 | N64: 2 | O64: 0.0625
B65: 23-Mar | C65: 91 | D65: 0.066740007 | L65: Nov | M65: 1 | N65: 4 | O65: 0.125
B66: 45739 | C66: 91 | D66: 0.066740007 | L66: 3-Nov | M66: 1 | N66: 4 | O66: 0.125
B67: 24-Mar | C67: 180 | D67: 0.1320132 | L67: Grand Total | M67: 13 | N67: 32 | O67: 1
B68: 45740 | C68: 180 | D68: 0.1320132
B69: Apr | C69: 91 | D69: 0.066740007
...

Sheet SalesDashboard
D1: SALES PERFORMANCE DASHBOARD
A3: =CleanSalesTable!N12 -> TotalOrders | B3: =CleanSalesTable!O12 -> 30 | D3: =CleanSalesTable!N13 -> TotalRevenue | E3: =CleanSalesTable!O13 -> 5827.5 | G3: =CleanSalesTable!N14 -> AvgOrderValue | H3: =CleanSalesTable!O14 -> 194.25 | J3: top product | K3: =CleanSalesTable!P15 -> 2437.5
K4: =CleanSalesTable!P16 -> Widget A
J5: Products | K5: =CleanSalesTable!N15 -> Widget A | L5: =CleanSalesTable!O15 -> 2437.5
K6: =CleanSalesTable!N16 -> Widget C | L6: =CleanSalesTable!O16 -> 1080
K7: =CleanSalesTable!N17 -> Widget B | L7: =CleanSalesTable!O17 -> 910
K8: =CleanSalesTable!N18 -> Widget D | L8: =CleanSalesTable!O18 -> 500
K9: =CleanSalesTable!N19 -> Widget E | L9: =CleanSalesTable!O19 -> 400
K10: =CleanSalesTable!N20 -> Widget G | L10: =CleanSalesTable!O20 -> 300
K11: =CleanSalesTable!N21 -> Widget F | L11: =CleanSalesTable!O21 -> 200
